<mujoco model="demo">
	<compiler angle="radian" autolimits="true" />
    <actuator>

        <!-- <motor joint="root_y"       name="torque_body_y"/> -->
        <!-- <motor joint="root_z"       name="torque_body_z"/> -->
        <!-- <motor joint="root_r"       name="torque_body_r"/> -->
        <!-- <motor joint="root_p"       name="torque_body_p"/> -->
        <!-- <motor joint="root_yw"      name="torque_body_yw"/> -1-> -->

        <motor joint="joint_right_hand"         name="torque_right_hand"    ctrllimited="true"     ctrlrange="-80.0 80.0"/>
        <motor joint="joint_right_hand_y"       name="torque_right_hand_y"  ctrllimited="true"     ctrlrange="-80.0 80.0"/>
        <motor joint="joint_right_hand_z"       name="torque_right_hand_z"  ctrllimited="true"     ctrlrange="-80.0 80.0"/>
        <motor joint="joint_right_hand_r"       name="torque_right_hand_r"  ctrllimited="true"     ctrlrange="-80.0 80.0"/>
        <motor joint="joint_right_hand_p"       name="torque_right_hand_p"  ctrllimited="true"     ctrlrange="-80.0 80.0"/>
        <motor joint="joint_right_hand_yw"      name="torque_right_hand_yw" ctrllimited="true"     ctrlrange="-80.0 80.0"/>

    </actuator>

    <asset>
        <mesh file="meshes/hand.stl" name="right_hand_mesh" scale="0.002 0.002 0.002"/>
        <mesh file="meshes/hand.stl" name="left_hand_mesh" scale="0.002 -0.002 0.002"/>
        <material name="MatMetal" specular="1" shininess="0.3" rgba="0.9 0.9 0.9 1" />
    </asset>

    <worldbody>
        <body name="floating_base" pos="-0.02 0.125 -0.34">
        <site name="right_center" pos="0 0 0" size="0.01" rgba="0.3 1.0 0.3 1" group="2" quat="1.0 0.0 0.0 0.0"/>
        <body>
            <!-- <joint name="root" axis="1 0 0"
                type="slide" limited="false"
                armature="0" stiffness="0" damping="0.0" frictionloss="0.99"
                /> -->
            <inertial pos="0 0 0" mass="1.0e-6" diaginertia="1.0e-9 1.0e-9 1.0e-9"/>
        <body>
            <!-- <joint name="root_y" axis="0 1 0"
                type="slide" limited="false"
                armature="0" stiffness="0" damping="0.0" frictionloss="0.99"
                /> -->
            <inertial pos="0 0 0" mass="1.0e-6" diaginertia="1.0e-9 1.0e-9 1.0e-9"/>
        <body>
            <!-- <joint name="root_z" axis="0 0 1"
                type="slide" limited="false"
                armature="0" stiffness="0" damping="0.0" frictionloss="0.99"
                /> -->
            <inertial pos="0 0 0" mass="1.0e-6" diaginertia="1.0e-9 1.0e-9 1.0e-9"/>
        <body>
            <!-- <joint name="root_r" axis="1 0 0"
                type="hinge" limited="false"
                armature="0" stiffness="0" damping="0.0" frictionloss="0.99"
                /> -->
            <inertial pos="0 0 0" mass="1.0e-6" diaginertia="1.0e-9 1.0e-9 1.0e-9"/>
        <body>
            <!-- <joint name="root_p" axis="0 1 0"
                type="hinge" limited="false"
                armature="0" stiffness="0" damping="0.0" frictionloss="0.99"
                /> -->
            <inertial pos="0 0 0" mass="1.0e-6" diaginertia="1.0e-9 1.0e-9 1.0e-9"/>
        <body name="base" pos="0 0 0.23">
            <inertial pos="0 0 0" mass="1.0e-1" diaginertia="1.0e-3 1.0e-3 1.0e-3"/>
            <!-- <joint name="root_yw" axis="0 0 1"
                type="hinge" limited="false"
                armature="0" stiffness="0" damping="0.0" frictionloss="0.99"
                /> -->
            <!-- <joint armature="0" damping="0" limited="false" name="root_quat" stiffness="0" type="ball"/> -->

            <geom type="sphere" size="0.1" pos="0 0 0.1"
                rgba="1.0 0.2 0.2 1"
                contype="0" conaffinity="0" group="1"
                />
            <geom type="sphere" size="0.075" pos="0 0 -0.1"
                rgba="1.0 0.2 0.2 1"
                contype="0" conaffinity="0" group="1"
                />

            <!-- <body pos="0.0 -0.2 -0.2"> -->
            <!-- <body pos="0.25 -0.04 -0.1"> -->
            <body pos="0.25 -0.25 -0.1">
                <joint name="joint_right_hand" axis="1 0 0"
                    type="slide" limited="true" range="-1.0 1.0"
                    armature="0" stiffness="0.0" damping="0.0"
                    />
                <inertial pos="0 0 0" mass="1.0e-6" diaginertia="1.0e-9 1.0e-9 1.0e-9"/>
            <body>
                <joint name="joint_right_hand_y" axis="0 1 0"
                    type="slide" limited="true" range="-1.0 1.0"
                    armature="0" stiffness="0.0" damping="0.0"
                    />
                <inertial pos="0 0 0" mass="1.0e-6" diaginertia="1.0e-9 1.0e-9 1.0e-9"/>
            <body>
                <joint name="joint_right_hand_z" axis="0 0 1"
                    type="slide" limited="true" range="-0.5 1.0"
                    armature="0" stiffness="0.0" damping="0.0"
                    />
                <inertial pos="0 0 0" mass="1.0e-6" diaginertia="1.0e-9 1.0e-9 1.0e-9"/>
            <body>
                <joint name="joint_right_hand_r" axis="1 0 0"
                    type="hinge" limited="true" range="-3.14 3.14"
                    armature="0" stiffness="0.0" damping="0.0"
                    />
                <inertial pos="0 0 0" mass="1.0e-6" diaginertia="1.0e-9 1.0e-9 1.0e-9"/>
            <body>
                <joint name="joint_right_hand_p" axis="0 1 0"
                    type="hinge" limited="true" range="-3.14 3.14"
                    armature="0" stiffness="0.0" damping="0.0"
                    />
                <inertial pos="0 0 0" mass="1.0e-6" diaginertia="1.0e-9 1.0e-9 1.0e-9"/>
            <!-- <body name="right_arm" pos="0.25 -0.04 -0.1"> -->
            <body name="right_arm" pos="0 0 0">
                <inertial pos="0 0 0" mass="1.0e-0" diaginertia="1.0e-4 1.0e-4 1.0e-4"/>
                <geom name='geom_right_hand_visual'
                    pos="-0.03 0.0 0.03" type="mesh" mesh="right_hand_mesh" quat="0.0 0.0 0 1.0"
                    group="1" contype="0" conaffinity="0"
                    rgba="1.0 0.2 0.2 0.2"
                    />
                <joint name="joint_right_hand_yw" axis="0 0 1"
                    type="hinge" limited="true" range="-3.14 3.14"
                    armature="0" stiffness="0.0" damping="0.0"
                    />
                <body name="right_eef_point" pos="0 0 0">
                    <!-- <body name="right_gripper_mount" pos="0 0 0" quat="0.5 0.5 0.5 0.5"> -->
                    <!-- <body name="right_gripper_mount" pos="0 0 0" quat="1.0 0.0 0.0 0.0"> -->
                    <!-- <body name="right_gripper_mount" pos="0 0 0" quat="0.7071 0.0 -0.7071 0.0"> -->
                    <body name="right_gripper_mount" pos="0 0 0" quat="-0.5 -0.5 0.5 0.5">
                        <camera mode="fixed" name="stereo_l_right_hand" pos="0.05 0.1 0.0" quat="0 1 0 0" fovy="120"/>
                        <camera mode="fixed" name="stereo_r_right_hand" pos="-0.05 0.1 0.0" quat="0 1 0 0" fovy="120"/>
                    </body>
                </body>
            </body>
            </body>
            </body>
            </body>
            </body>
            </body>


        </body>
        </body>
        </body>
        </body>
        </body>
        </body>

        </body>
    </worldbody>
</mujoco>
